Workbook

Sheet Assumptions
A1: ASSUMPTIONS | B1: Year 1 | C1: Year 2 | D1: Year 3 | E1: Notes
A2: SHOWS — EXTERNAL (revenue-generating)
A3: Prophecy — External shows (China) | B3: 2 | C3: 8 | D3: 13 | E3: Booked by INS in external venues
A4: Prophecy — Fee per external show | B4: 4500 | C4: 5500 | D4: 7000 | E4: Paid by external promoter
A5: Björn — External shows (China) | B5: 1 | C5: 7 | D5: 13 | E5: Booked by INS
A6: Björn — Fee per external show | B6: 1500 | C6: 2500 | D6: 4000 | E6: Grows with catalog
A7: AIRE — External shows (China) | B7: 1 | C7: 4 | D7: 6 | E7: Booked by INS
A8: AIRE — Fee per external show | B8: 3500 | C8: 4500 | D8: 6000 | E8: Premium format
A10: SHOWS — INS VENUES (cost to INS)
A11: Prophecy — INS venue shows | B11: 2 | C11: 2 | D11: 2 | E11: Showcase + ghost prod exchange
A12: Prophecy — Fee per INS show | B12: 4000 | C12: 4500 | D12: 5000 | E12: Cash paid to Prophecy
A13: AIRE — INS venue shows | B13: 2 | C13: 2 | D13: 2 | E13: Immersive format showcase
A14: AIRE — Fee per INS show | B14: 3500 | C14: 4000 | D14: 5000 | E14: Cash paid to AIRE
A15: Björn — INS venue shows | B15: 3 | C15: 3 | D15: 2 | E15: Own artist — no fee
A16: INS venue marginal cost per show | B16: 500 | C16: 500 | D16: 500 | E16: Sound, promo, logistics per show
A18: GHOST PRODUCTION (A2G delivers)
A19: Tracks produced for Björn | B19: 4 | C19: 6 | D19: 8 | E19: By Prophecy
A20: Market value per track | B20: 3500 | C20: 3500 | D20: 3500 | E20: €5-15K on open market
A22: REVENUE SHARE — INS % PER YEAR
A23: INS share Year 1 | B23: 0.6 | E23: Phase 1: Recovery
A24: INS share Year 2 | B24: 0.6 | E24: Phase 1 continues or transitions
A25: INS share Year 3 | B25: 0.6 | E25: Phase 1 continues — breakeven not reached Y2
A26: Year 4-5 (post-breakeven): 30% for 3yr | E26: Phase 2 starts after breakeven
A27: Year 6-10: 10% for 5 years | E27: Phase 3
A28: OTHER REVENUE STREAMS
A29: Streaming — China territory | B29: 5000 | C29: 15000 | D29: 40000 | E29: QQ Music, NetEase, Douyin
A30: Sync & gaming | B30: 5000 | C30: 12000 | D30: 25000 | E30: Hero E-Sports pipeline
A31: Content licensing — AIRE A/V | B31: 3000 | C31: 8000 | D31: 15000 | E31: From every activation
A32: Merchandise | B32: 0 | C32: 3000 | D32: 5000 | E32: Scales with audience
A34: INS OTHER CASH COSTS
A35: Marketing campaigns | B35: 13000 | C35: 25000 | D35: 40000 | E35: Douyin, RED, local promo
A36: AIRE content production | B36: 6000 | C36: 8000 | D36: 10000 | E36: A/V post-production
A37: Scouting & artist dev | B37: 5000 | C37: 8000 | D37: 10000 | E37: Pipeline building

Sheet Financial Model
A1: A2G × INS — 3-YEAR FINANCIAL MODEL | B1: Year 1 | C1: Year 2 | D1: Year 3 | E1: 3-Year Total
A2: GROSS REVENUE (all artists, China territory)
A3: Prophecy — External shows | B3: =Assumptions!B3*Assumptions!B4 -> 9000 | C3: =Assumptions!C3*Assumptions!C4 -> 44000 | D3: =Assumptions!D3*Assumptions!D4 -> 91000 | E3: =SUM(B3:D3) -> 144000
A4: Björn — External shows | B4: =Assumptions!B5*Assumptions!B6 -> 1500 | C4: =Assumptions!C5*Assumptions!C6 -> 17500 | D4: =Assumptions!D5*Assumptions!D6 -> 52000 | E4: =SUM(B4:D4) -> 71000
A5: AIRE — External shows | B5: =Assumptions!B7*Assumptions!B8 -> 3500 | C5: =Assumptions!C7*Assumptions!C8 -> 18000 | D5: =Assumptions!D7*Assumptions!D8 -> 36000 | E5: =SUM(B5:D5) -> 57500
A6: Streaming — China territory | B6: =Assumptions!B29 -> 5000 | C6: =Assumptions!C29 -> 15000 | D6: =Assumptions!D29 -> 40000 | E6: =SUM(B6:D6) -> 60000
A7: Sync & gaming | B7: =Assumptions!B30 -> 5000 | C7: =Assumptions!C30 -> 12000 | D7: =Assumptions!D30 -> 25000 | E7: =SUM(B7:D7) -> 42000
A8: Content licensing — AIRE A/V | B8: =Assumptions!B31 -> 3000 | C8: =Assumptions!C31 -> 8000 | D8: =Assumptions!D31 -> 15000 | E8: =SUM(B8:D8) -> 26000
A9: Merchandise | B9: =Assumptions!B32 -> 0 | C9: =Assumptions!C32 -> 3000 | D9: =Assumptions!D32 -> 5000 | E9: =SUM(B9:D9) -> 8000
A10: TOTAL GROSS REVENUE | B10: =SUM(B3:B9) -> 27000 | C10: =SUM(C3:C9) -> 117500 | D10: =SUM(D3:D9) -> 264000 | E10: =SUM(B10:D10) -> 408500
A12: INS REVENUE (Phase 1: 60% all 3 years — breakeven not reached)
A13: Prophecy shows (Y1: 60% · Y2: 60% · Y3: 60%) | B13: =B3*Assumptions!B23 -> 5400 | C13: =C3*Assumptions!B24 -> 26400 | D13: =D3*Assumptions!B25 -> 54600 | E13: =SUM(B13:D13) -> 86400
A14: Björn shows (Y1: 60% · Y2: 60% · Y3: 60%) | B14: =B4*Assumptions!B23 -> 900 | C14: =C4*Assumptions!B24 -> 10500 | D14: =D4*Assumptions!B25 -> 31200 | E14: =SUM(B14:D14) -> 42600
A15: AIRE shows (Y1: 60% · Y2: 60% · Y3: 60%) | B15: =B5*Assumptions!B23 -> 2100 | C15: =C5*Assumptions!B24 -> 10800 | D15: =D5*Assumptions!B25 -> 21600 | E15: =SUM(B15:D15) -> 34500
A16: Streaming (Y1: 60% · Y2: 60% · Y3: 60%) | B16: =B6*Assumptions!B23 -> 3000 | C16: =C6*Assumptions!B24 -> 9000 | D16: =D6*Assumptions!B25 -> 24000 | E16: =SUM(B16:D16) -> 36000
A17: Sync & gaming (Y1: 60% · Y2: 60% · Y3: 60%) | B17: =B7*Assumptions!B23 -> 3000 | C17: =C7*Assumptions!B24 -> 7200 | D17: =D7*Assumptions!B25 -> 15000 | E17: =SUM(B17:D17) -> 25200
A18: Content licensing (Y1: 60% · Y2: 60% · Y3: 60%) | B18: =B8*Assumptions!B23 -> 1800 | C18: =C8*Assumptions!B24 -> 4800 | D18: =D8*Assumptions!B25 -> 9000 | E18: =SUM(B18:D18) -> 15600
A19: Merchandise (Y1: 60% · Y2: 60% · Y3: 60%) | B19: =B9*Assumptions!B23 -> 0 | C19: =C9*Assumptions!B24 -> 1800 | D19: =D9*Assumptions!B25 -> 3000 | E19: =SUM(B19:D19) -> 4800
A20: TOTAL INS REVENUE | B20: =SUM(B13:B19) -> 16200 | C20: =SUM(C13:C19) -> 70500 | D20: =SUM(D13:D19) -> 158400 | E20: =SUM(B20:D20) -> 245100
A22: INS CASH INVESTMENT (all cash out)
A23: Prophecy — INS venue show fees | B23: =Assumptions!B11*Assumptions!B12 -> 8000 | C23: =Assumptions!C11*Assumptions!C12 -> 9000 | D23: =Assumptions!D11*Assumptions!D12 -> 10000 | E23: =SUM(B23:D23) -> 27000
A24: AIRE — INS venue show fees | B24: =Assumptions!B13*Assumptions!B14 -> 7000 | C24: =Assumptions!C13*Assumptions!C14 -> 8000 | D24: =Assumptions!D13*Assumptions!D14 -> 10000 | E24: =SUM(B24:D24) -> 25000
A25: INS venue costs (all shows) | B25: =(Assumptions!B11+Assumptions!B13+Assumptions!B15)*Assumptions!B16 -> 3500 | C25: =(Assumptions!C11+Assumptions!C13+Assumptions!C15)*Assumptions!C16 -> 3500 | D25: =(Assumptions!D11+Assumptions!D13+Assumptions!D15)*Assumptions!D16 -> 3000 | E25: =SUM(B25:D25) -> 10000
A26: Marketing campaigns | B26: =Assumptions!B35 -> 13000 | C26: =Assumptions!C35 -> 25000 | D26: =Assumptions!D35 -> 40000 | E26: =SUM(B26:D26) -> 78000
A27: AIRE content production | B27: =Assumptions!B36 -> 6000 | C27: =Assumptions!C36 -> 8000 | D27: =Assumptions!D36 -> 10000 | E27: =SUM(B27:D27) -> 24000
A28: Scouting & artist dev | B28: =Assumptions!B37 -> 5000 | C28: =Assumptions!C37 -> 8000 | D28: =Assumptions!D37 -> 10000 | E28: =SUM(B28:D28) -> 23000
A29: TOTAL INS CASH INVESTMENT | B29: =SUM(B23:B28) -> 42500 | C29: =SUM(C23:C28) -> 61500 | D29: =SUM(D23:D28) -> 83000 | E29: =SUM(B29:D29) -> 187000
A31: VALUE RECEIVED BY INS (no cash)
A32: Ghost production (tracks × market value) | B32: =Assumptions!B19*Assumptions!B20 -> 14000 | C32: =Assumptions!C19*Assumptions!C20 -> 21000 | D32: =Assumptions!D19*Assumptions!D20 -> 28000 | E32: =SUM(B32:D32) -> 63000
A34: SUMMARY
A35: INS Cash Out (annual) | B35: =B29 -> 42500 | C35: =C29 -> 61500 | D35: =D29 -> 83000 | E35: =SUM(B35:D35) -> 187000
A36: INS Revenue (annual) | B36: =B20 -> 16200 | C36: =C20 -> 70500 | D36: =D20 -> 158400 | E36: =SUM(B36:D36) -> 245100
A37: Net Cash Flow (annual) | B37: =B36-B35 -> -26300 | C37: =C36-C35 -> 9000 | D37: =D36-D35 -> 75400 | E37: =SUM(B37:D37) -> 58100
A39: INS Cash Out (cumulative) | B39: =B35 -> 42500 | C39: =B39+C35 -> 104000 | D39: =C39+D35 -> 187000 | E39: =D39 -> 187000
A40: INS Revenue (cumulative) | B40: =B36 -> 16200 | C40: =B40+C36 -> 86700 | D40: =C40+D36 -> 245100 | E40: =D40 -> 245100
A41: Net Cumulative | B41: =B40-B39 -> -26300 | C41: =C40-C39 -> -17300 | D41: =D40-D39 -> 58100 | E41: =SUM(B41:D41) -> 14500
A42: % Investment Recovered | B42: =IF(B39=0,0,B40/B39) -> 0.38117647 | C42: =IF(C39=0,0,C40/C39) -> 0.83365385 | D42: =IF(D39=0,0,D40/D39) -> 1.3106952 | E42: =IF(E39=0,0,E40/E39) -> 1.3106952
A44: + Value trade received (ghost production) | B44: =B32 -> 14000 | C44: =C32 -> 21000 | D44: =D32 -> 28000 | E44: =SUM(B44:D44) -> 63000
A45: Total value returned (revenue + production) | B45: =B36+B44 -> 30200 | C45: =C36+C44 -> 91500 | D45: =D36+D44 -> 186400 | E45: =SUM(B45:D45) -> 308100
A47: NOT INCLUDED IN THIS MODEL (additional INS upside):
...
